<?xml version="1.0" encoding="UTF-8"?>
<!-- Generated by org.testng.reporters.JUnitXMLReporter -->
<testsuite hostname="ADMIN" failures="2" tests="16" name="Default test" time="0.159" errors="0" timestamp="3 Aug 2022 11:58:38 GMT">
  <testcase classname="testng_Failed.SecondClassTest" name="testMethod1" time="0.02"/>
  <testcase classname="testng_Failed.SecondClassTest" name="testMethod2" time="0.002"/>
  <testcase classname="testng_Failed.SecondClassTest" name="testMethod3" time="0.003"/>
  <testcase classname="testng_Failed.SecondClassTest" name="testMethod4" time="0.003"/>
  <testcase classname="testng_Failed.SecondClassTest" name="testMethod5" time="0.007">
    <skipped/>
  </testcase> <!-- testMethod5 -->
  <testcase classname="testng_Failed.SecondClassTest" name="testMethod5" time="0.004">
    <skipped/>
  </testcase> <!-- testMethod5 -->
  <testcase classname="testng_Failed.SecondClassTest" name="testMethod5" time="0.003">
    <skipped/>
  </testcase> <!-- testMethod5 -->
  <testcase classname="testng_Failed.SecondClassTest" name="testMethod5" time="0.002">
    <failure type="java.lang.AssertionError" message="null">
      <![CDATA[java.lang.AssertionError: null
	at org.testng.Assert.fail(Assert.java:94)
	at org.testng.Assert.fail(Assert.java:101)
	at testng_Failed.SecondClassTest.testMethod5(SecondClassTest.java:35)
	at java.base/jdk.internal.reflect.NativeMethodAccessorImpl.invoke0(Native Method)
	at java.base/jdk.internal.reflect.NativeMethodAccessorImpl.invoke(NativeMethodAccessorImpl.java:77)
	at java.base/jdk.internal.reflect.DelegatingMethodAccessorImpl.invoke(DelegatingMethodAccessorImpl.java:43)
	at java.base/java.lang.reflect.Method.invoke(Method.java:568)
	at org.testng.internal.MethodInvocationHelper.invokeMethod(MethodInvocationHelper.java:85)
	at org.testng.internal.Invoker.invokeMethod(Invoker.java:639)
	at org.testng.internal.Invoker.retryFailed(Invoker.java:963)
	at org.testng.internal.Invoker.invokeTestMethods(Invoker.java:1142)
	at org.testng.internal.TestMethodWorker.invokeTestMethods(TestMethodWorker.java:125)
	at org.testng.internal.TestMethodWorker.run(TestMethodWorker.java:108)
	at org.testng.TestRunner.privateRun(TestRunner.java:774)
	at org.testng.TestRunner.run(TestRunner.java:624)
	at org.testng.SuiteRunner.runTest(SuiteRunner.java:359)
	at org.testng.SuiteRunner.runSequentially(SuiteRunner.java:354)
	at org.testng.SuiteRunner.privateRun(SuiteRunner.java:312)
	at org.testng.SuiteRunner.run(SuiteRunner.java:261)
	at org.testng.SuiteRunnerWorker.runSuite(SuiteRunnerWorker.java:52)
	at org.testng.SuiteRunnerWorker.run(SuiteRunnerWorker.java:86)
	at org.testng.TestNG.runSuitesSequentially(TestNG.java:1191)
	at org.testng.TestNG.runSuitesLocally(TestNG.java:1116)
	at org.testng.TestNG.run(TestNG.java:1024)
	at org.testng.remote.AbstractRemoteTestNG.run(AbstractRemoteTestNG.java:115)
	at org.testng.remote.RemoteTestNG.initAndRun(RemoteTestNG.java:251)
	at org.testng.remote.RemoteTestNG.main(RemoteTestNG.java:77)
]]>
    </failure>
  </testcase> <!-- testMethod5 -->
  <testcase classname="testng_Failed.FirstClassTest" name="testMethod1" time="0.003"/>
  <testcase classname="testng_Failed.FirstClassTest" name="testMethod2" time="0.002"/>
  <testcase classname="testng_Failed.FirstClassTest" name="testMethod3" time="0.002"/>
  <testcase classname="testng_Failed.FirstClassTest" name="testMethod4" time="0.002"/>
  <testcase classname="testng_Failed.FirstClassTest" name="testMethod5" time="0.003">
    <skipped/>
  </testcase> <!-- testMethod5 -->
  <testcase classname="testng_Failed.FirstClassTest" name="testMethod5" time="0.003">
    <skipped/>
  </testcase> <!-- testMethod5 -->
  <testcase classname="testng_Failed.FirstClassTest" name="testMethod5" time="0.004">
    <skipped/>
  </testcase> <!-- testMethod5 -->
  <testcase classname="testng_Failed.FirstClassTest" name="testMethod5" time="0.002">
    <failure type="java.lang.AssertionError" message="null">
      <![CDATA[java.lang.AssertionError: null
	at org.testng.Assert.fail(Assert.java:94)
	at org.testng.Assert.fail(Assert.java:101)
	at testng_Failed.FirstClassTest.testMethod5(FirstClassTest.java:35)
	at java.base/jdk.internal.reflect.NativeMethodAccessorImpl.invoke0(Native Method)
	at java.base/jdk.internal.reflect.NativeMethodAccessorImpl.invoke(NativeMethodAccessorImpl.java:77)
	at java.base/jdk.internal.reflect.DelegatingMethodAccessorImpl.invoke(DelegatingMethodAccessorImpl.java:43)
	at java.base/java.lang.reflect.Method.invoke(Method.java:568)
	at org.testng.internal.MethodInvocationHelper.invokeMethod(MethodInvocationHelper.java:85)
	at org.testng.internal.Invoker.invokeMethod(Invoker.java:639)
	at org.testng.internal.Invoker.retryFailed(Invoker.java:963)
	at org.testng.internal.Invoker.invokeTestMethods(Invoker.java:1142)
	at org.testng.internal.TestMethodWorker.invokeTestMethods(TestMethodWorker.java:125)
	at org.testng.internal.TestMethodWorker.run(TestMethodWorker.java:108)
	at org.testng.TestRunner.privateRun(TestRunner.java:774)
	at org.testng.TestRunner.run(TestRunner.java:624)
	at org.testng.SuiteRunner.runTest(SuiteRunner.java:359)
	at org.testng.SuiteRunner.runSequentially(SuiteRunner.java:354)
	at org.testng.SuiteRunner.privateRun(SuiteRunner.java:312)
	at org.testng.SuiteRunner.run(SuiteRunner.java:261)
	at org.testng.SuiteRunnerWorker.runSuite(SuiteRunnerWorker.java:52)
	at org.testng.SuiteRunnerWorker.run(SuiteRunnerWorker.java:86)
	at org.testng.TestNG.runSuitesSequentially(TestNG.java:1191)
	at org.testng.TestNG.runSuitesLocally(TestNG.java:1116)
	at org.testng.TestNG.run(TestNG.java:1024)
	at org.testng.remote.AbstractRemoteTestNG.run(AbstractRemoteTestNG.java:115)
	at org.testng.remote.RemoteTestNG.initAndRun(RemoteTestNG.java:251)
	at org.testng.remote.RemoteTestNG.main(RemoteTestNG.java:77)
]]>
    </failure>
  </testcase> <!-- testMethod5 -->
</testsuite> <!-- Default test -->
